Workbook

Sheet Dotación Obra
B2: CARGO | C2: ECO05 | D2: ODS N°1 | E2: TOTAL | G2: DOT. TOTAL AJUSTADA
B3: JEFE DE TURNO | C3: 4 | D3: 4 | E3: =C3+D3 -> 8 | G3: =E3 -> 8
B4: PREVENCIONISTA DE TURNO | C4: 4 | D4: 4 | E4: =C4+D4 -> 8 | G4: =E4 -> 8
B5: INGENIERO SALA DE CONTROL | C5: 4 | D5: 0 | E5: =C5+D5 -> 4 | G5: =E5 -> 4
B6: LIDER ELECTRICISTA | C6: 0 | D6: 4 | E6: =C6+D6 -> 4 | G6: =E6 -> 4
B7: MAESTRO ELECTRICISTAS | C7: =6+5 -> 11 | D7: 6 | E7: =C7+D7 -> 17 | G7: =8+6 -> 14
B8: AYUDANTE ELECTRICISTA | C8: 4 | D8: 0 | E8: =C8+D8 -> 4 | G8: 0
B9: LIDER MECÁNICO | C9: 0 | D9: 4 | E9: =C9+D9 -> 4 | G9: =E9 -> 4
B10: MAESTRO MECANICO | C10: 12 | D10: 2 | E10: =C10+D10 -> 14 | G10: =E10 -> 14
B11: MECÁNICO ESPECIALISTA | C11: 0 | D11: 4 | E11: =C11+D11 -> 4 | G11: =E11 -> 4
B12: MECANICO MANTENCIÓN | C12: 0 | D12: 2 | E12: =C12+D12 -> 2 | G12: =E12 -> 2
B13: VULCANIZADOR | C13: 0 | D13: 0 | E13: =C13+D13 -> 0 | G13: =E13 -> 0
B14: SOLDADOR MANTENCION | C14: 2 | D14: 0 | E14: =C14+D14 -> 2 | G14: =E14 -> 2
B15: ELECTROMECANICO | C15: 4 | D15: 0 | E15: =C15+D15 -> 4 | G15: =E15 -> 4
B16: ELECTRONICO | C16: 2 | D16: 2 | E16: =C16+D16 -> 4 | G16: =E16 -> 4
B17: INSTRUCTOR BOLTEC | C17: 0 | D17: 1 | E17: =C17+D17 -> 1 | G17: =E17 -> 1
B18: BODEGUERO | C18: 4 | D18: 4 | E18: =C18+D18 -> 8 | G18: =E18 -> 8
B19: BODEGUERO/COMPRADOR | C19: 0 | D19: 1 | E19: =C19+D19 -> 1 | G19: =E19 -> 1
B20: CHOFER SERVICIOS | C20: 14 | D20: 7 | E20: =C20+D20 -> 21 | G20: =E20 -> 21
... B25: OPERADOR ROBOSHOT | C25: 4 | D25: 4 | E25: =C25+D25 -> 8 | G25: =E25 -> 8
B26: OPERADOR BOMBA DE HORMIGÓN | C26: 8 | D26: 0 | E26: =C26+D26 -> 8 | G26: 0
B27: OPERADOR RETROEXCAVADORA - ACUÑADOR | C27: 8 | D27: 0 | E27: =C27+D27 -> 8 | G27: =E27 -> 8
B28: OPERADOR MIXER | C28: 0 | D28: 8 | E28: =C28+D28 -> 8 | G28: =E28 -> 8
B29: OPERADOR BROKK | C29: 0 | D29: 4 | E29: =C29+D29 -> 4 | G29: =E29 -> 4
B30: OPERADOR EQUIPO LEVANTE/ MINI CARGADOR | C30: 32 | D30: 16 | E30: =C30+D30 -> 48 | G30: =E30 -> 48
B31: CAPATAZ MINERIA - OOCC | C31: 32 | D31: 16 | E31: =C31+D31 -> 48 | G31: =E31 -> 48
B32: MAESTRO MINERÍA - OOCC | C32: 56 | D32: 32 | E32: =C32+D32 -> 88 | G32: =E32 -> 88
B33: AYUDANTE MINERÍA - OOCC | C33: =4*7 -> 28 | D33: 0 | E33: =C33+D33 -> 28 | G33: =E33 -> 28
B34: SOLDADOR MONTAJE (MINERÍA Y OOCC) | C34: 0 | D34: 16 | E34: =C34+D34 -> 16 | G34: =E34 -> 16
B35: SUPERVISOR MONTAJE | C35: 0 | D35: 1 | E35: =C35+D35 -> 1 | G35: =E35 -> 1
B36: CAPATAZ MONTAJE | C36: 4 | D36: 0 | E36: =C36+D36 -> 4 | G36: =E36 -> 4
B37: MAESTRO MONTAJE | C37: 12 | D37: 0 | E37: =C37+D37 -> 12 | G37: =E37 -> 12
B38: AYUDANTE MONTAJE | C38: 4 | D38: 0 | E38: =C38+D38 -> 4 | G38: =E38 -> 4
B39: SOLDADOR MONTAJE | C39: 4 | D39: 0 | E39: =C39+D39 -> 4 | G39: =E39 -> 4
B40: CAPATAZ MISCELÁNEOS | C40: 0 | D40: 1 | E40: =C40+D40 -> 1 | G40: =E40 -> 1
B41: MAESTRO AVANZADO MISCELÁNEOS | C41: 0 | D41: 1 | E41: =C41+D41 -> 1 | G41: =E41 -> 1
B42: MAESTRO OOCC MISCELÁNEOS | C42: 0 | D42: 1 | E42: =C42+D42 -> 1 | G42: =E42 -> 1
B43: AYUDANTE MISCELÁNEOS | C43: 0 | D43: 1 | E43: =C43+D43 -> 1 | G43: =E43 -> 1
B44: SOLDADOR MONTAJE MISCELÁNEOS | C44: 0 | D44: 1 | E44: =C44+D44 -> 1 | G44: =E44 -> 1
B45: CD+CI | C45: =SUM(C3:C44) -> 277 | D45: =SUM(D3:D44) -> 155 | E45: =SUM(E3:E44) -> 432 | G45: =SUM(G3:G44) -> 417
...

Sheet Grilla ODS
B2: DEPARTAMENTO | C2: CARGO | D2: GRUPO 1 | E2: EST G1 | F2: LIC G1 | G2: GRUPO 2 | H2: EST G2 | I2: LIC G2 | J2: GRUPO 3 | K2: EST G3 | L2: LIC G3 | M2: GRUPO 4 | N2: EST G4 | O2: LIC G4 | P2: BASE | Q2: ODS1 | R2: ODS ok | T2: DOT. TOTAL
C3: SUPERVISIÓN
B4: OPERACIÓN | C4: JEFE DE TURNO 1 | D4: DROGUETT MUÑOZ MARCOS ANTONIO | E4: A | F4: L | G4: ALDUNCE DEVIA MIGUEL ANGEL | H4: A | I4: L | J4: URZUA DELGADO RODRIGO ISMAEL | K4: A | M4: HORMAZABAL SOTO HERNAN ENRIQUE | N4: A | P4: 4 | T4: =SUM(P4:Q4) -> 4
B5: OPERACIÓN | C5: JEFE DE TURNO 2 | D5: REUSSIER MANRIQUEZ OMAR JAMPIER | E5: A | G5: LEIVA BECERRA JAVIER ANTONIO | H5: A | J5: REYES JOHNSON CLAUDIO ANDRÉS | K5: A | L5: L | M5: GARRIDO CASTILLO CRISTOFER NIVALDO | N5: A | Q5: 4 | R5: 4 | S5: =+COUNTIF(D5:O5,"A")+COUNTIF(D5:O5,"C") -> 4 | T5: =SUM(P5:Q5) -> 4 | W5: Puestos adicionales por Ampliacion
B6: SEGURIDAD | C6: APR 1 | D6: ROJAS HERNANDEZ MARIO ANIBAL | E6: A | G6: OPAZO PALMA KAREN GRACIELA | H6: A | J6: INZUNZA ÓRDENES SANTIAGO ABRAHAM | K6: A | M6: RODRIGO POBLETE | N6: A | P6: 4 | T6: =SUM(P6:Q6) -> 4 | W6: Vacantes disponibles contrato actual
B7: SEGURIDAD | C7: APR 2 | D7: PACHECO HERRERA PABLO (5x2) | E7: A | G7: MUÑOZ SAN MARTIN RODRIGO ESTEBAN | H7: P | J7: CASTILLO GONZALEZ RAUL RENE | K7: A | M7: ORDENES ROJAS JUAN ENRIQUE | N7: C | Q7: 4 | R7: 2 | S7: =+COUNTIF(D7:O7,"A")+COUNTIF(D7:O7,"C") -> 3 | T7: =SUM(P7:Q7) -> 4
B8: OFICINA TECNICA | C8: SALA CONTROL | D8: SALAZAR RODRIGUEZ CARLOS ALBERTO | E8: A | G8: ARRIAZA VIDAL MARTIN ENRIQUE | H8: A | J8: COLOMA TOLEDO ALVARO ALBERTO | K8: A | M8: HENRIQUEZ ORTIZ MARCELO JAVIER | N8: A | P8: 4 | T8: =SUM(P8:Q8) -> 4
C9: SOPORTE OPERACIÓN | T9: =SUM(P9:Q9) -> 0
B10: ELECTRICO | C10: LÍDER ELECTRICISTA | D10: SEGUEL CISTERNA JEAN LESTER | E10: A | F10: L | G10: PEREZ BOBADILLA LUIS ALEJANDRO | H10: A | J10: SOTO SEVERINO ROBERTO ANTONIO | K10: A | L10: L | M10: GUTIERREZ VALENZUELA CARLOS ANDRES | N10: A | Q10: 4 | R10: 4 | S10: =+COUNTIF(D10:O10,"A")+COUNTIF(D10:O10,"C") -> 4 | T10: =SUM(P10:Q10) -> 4
B11: ELECTRICO | C11: MAESTRO ELECTRICISTA 1 | D11: RIVERA URRA DIXON ANTONIO | E11: A | G11: FONSECA FARIAS ANGEL DANIEL | H11: A | J11: REYES OCAMPO MARIO RAFAEL | K11: A | N11: v | P11: 4 | T11: =SUM(P11:Q11) -> 4
B12: ELECTRICO | C12: MAESTRO ELECTRICISTA 2 | D12: SANDOVAL CANTILLANA BRIAN DANIEL | E12: A | G12: MIRANDA REYES CESAR EDUARDO | H12: A | J12: AYALA PINO FERNANDO ANTONIO | K12: A | M12: SANDOVAL CANTILLANA MATIAS NICOLAS | N12: A | P12: 4 | T12: =SUM(P12:Q12) -> 4
B13: ELECTRICO | C13: MAESTRO ELECTRICISTA 3 | D13: GONZALEZ JARA MANUEL ALEJANDRO | E13: A | H13: V | J13: GUZMAN ZAMORANO RAUL ANDRES | K13: A | M13: VALDIVIA MENARES SERGIO ANDRES | N13: P | Q13: 4 | R13: 2 | S13: =+COUNTIF(D13:O13,"A")+COUNTIF(D13:O13,"C") -> 2 | T13: =SUM(P13:Q13) -> 4
B14: ELECTRICO | C14: ELECTRÓNICO | D14: CARRASCO GUTIERREZ PABLO JAVIER | E14: A | G14: ORTEGA HERRERA JUAN DANIEL | H14: C | J14: LOPEZ BARRAZA ALEXANDER ESTEBAN | K14: A | M14: AGURTO CUADRA LUIS DANIEL | N14: A | P14: 2 | Q14: 2 | R14: 2 | S14: =+COUNTIF(D14:O14,"A")+COUNTIF(D14:O14,"C") -> 4 | T14: =SUM(P14:Q14) -> 4
B15: MECANICO | C15: LÍDER MECÁNICO | D15: REYES GONZALEZ JOSE IGNACIO | E15: A | G15: VALDIVIA PEREZ HERNAN ALEJANDRO | H15: A | J15: PONCE JAÑA PABLO ENRIQUE | K15: A | M15: LOPEZ BUSTAMANTE CARLOS ENRIQUE | N15: A | Q15: 4 | R15: 4 | S15: =+COUNTIF(D15:O15,"A")+COUNTIF(D15:O15,"C") -> 4 | T15: =SUM(P15:Q15) -> 4
B16: MECANICO | C16: MAESTRO MECÁNICO 1 | D16: GONZALEZ CACERES PATRICIO OCTAVIO | E16: A | G16: REDONDO JIMENEZ FELIPE ANDRES | H16: A | J16: NUÑEZ LEON VICTOR MANUEL | K16: A | M16: TORRES TORRES EDUARDO ANDRES | N16: A | P16: 4 | T16: =SUM(P16:Q16) -> 4
B17: MECANICO | C17: MAESTRO MECÁNICO 2 | D17: FELIPE SALAZAR | E17: A | G17: VICTOR PARRA | H17: A | J17: VILLARROEL NUÑEZ VICENTE ANTONIO | K17: A | M17: JAVIER IGNACIO VERGARA AGUILAR | N17: A | P17: 4 | T17: =SUM(P17:Q17) -> 4
B18: MECANICO | C18: MAESTRO MECÁNICO 3 | D18: JOSE RUBIO SAEZ | E18: A | G18: PABLO VAZQUEZ MIRANDA | H18: A | J18: CRISTOBAL MUÑOZ TERAN | K18: A | M18: EDSON MEDINA CORONADO | N18: A | P18: 4 | T18: =SUM(P18:Q18) -> 4
B19: MECANICO | C19: ELECTROMECÁNICO | D19: ABARCA ESPINOZA JUAN JOSE | E19: A | G19: CATEJO RIQUELME LUIS RODRIGO | H19: A | J19: ALARCÓN PALMA RICARDO | K19: A | M19: VICENTE ALBIÑA | N19: A | P19: 4 | T19: =SUM(P19:Q19) -> 4
B20: OPERACIÓN | C20: BODEGUERO 1 | D20: NARVÁEZ BÓRQUEZ CHRISTIAN MARCELO | E20: A | G20: TOBAR VERGARA JUAN PABLO | H20: A | J20: CORREA GALDAMES MAURICIO ALFONSO | K20: A | M20: BONET MEDINA JOSÉ | N20: A | P20: 4 | T20: =SUM(P20:Q20) -> 4
B21: OPERACIÓN | C21: CHOFER DE SERVICIOS 1 | D21: CARVAJAL AHUMADA JUAN ENRIQUE | E21: A | G21: MONSALVE VILLA RODRIGO IGNACIO | H21: A | I21: L | J21: URZUA PIÑA ALEJANDRO ESTEBAN | K21: A | M21: GUAJARDO MIRANDA BRUNO SEBASTIAN | N21: A | O21: L | P21: 4 | T21: =SUM(P21:Q21) -> 4
B22: OPERACIÓN | C22: CHOFER DE SERVICIOS 2 | D22: ULLOA BERRIOS RICHARD ROSENDO | E22: A | F22: L | G22: ARANGUIZ CASTRO JOSE MIGUEL | H22: P | J22: GAJARDO CORDERO FERNANDO BASTIAN | K22: A | M22: GUTIERREZ SOTO MAURICIO RENE | N22: A | O22: L | P22: 4 | T22: =SUM(P22:Q22) -> 4
B23: OPERACIÓN | C23: CHOFER DE SERVICIOS 3 | D23: MORENO PALMA OSVALDO ENRIQUE | E23: A | F23: L | G23: PEREZ AVILA SEBASTIAN SAMUEL | H23: A | J23: FAUNDEZ ROMERO PATRICIO RICARDO | K23: A | M23: VARGAS ORREGO PIA FRANCISCA | N23: A | P23: 3 | Q23: 1 | R23: 1 | S23: =+COUNTIF(D23:O23,"A")+COUNTIF(D23:O23,"C") -> 4 | T23: =SUM(P23:Q23) -> 4
C24: EQUIPOS MINERÍA Y OOCC | T24: =SUM(P24:Q24) -> 0
B25: OPERADOR | C25: OPERADOR JUMBO FORTIFICACION 1 | D25: PEREZ YAÑEZ HECTOR EDUARDO | E25: A | G25: YAÑEZ GARCIA ERASMO ERNESTO | H25: A | I25: L | J25: ADASME ROJAS LUIS MAURICIO | K25: A | L25: L | M25: GONZALEZ MORENO FRANCISCO JAVIER | N25: A | P25: 4 | T25: =SUM(P25:Q25) -> 4
B26: OPERADOR | C26: OPERADOR JUMBO FORTIFICACION 2 | D26: ZAMORA PINO VICTOR MANUEL | E26: A | F26: L | G26: HERNANDEZ ESPINOZA JOSE ANTONIO | H26: A | I26: L | J26: GONZALEZ QUISPE MARCO ANDRES | K26: A | L26: L | M26: MORENO MORENO ALEJANDRO ANTONIO | N26: A | O26: L | P26: 4 | T26: =SUM(P26:Q26) -> 4
B27: OPERADOR | C27: OPERADOR JUMBO FORTIFICACION 3 | D27: MAUREIRA ROMERO FELIPE ANDRES | E27: A | F27: L | G27: RIVERA DIAZ RAUL ALEJANDRO | H27: C | J27: ROJAS MILLA JOSE LUIS | K27: C | M27: MOLLO ARAYA EDUARDO WALTER | N27: C | Q27: 4 | R27: 1 | S27: =+COUNTIF(D27:O27,"A")+COUNTIF(D27:O27,"C") -> 4 | T27: =SUM(P27:Q27) -> 4
B28: OPERADOR | C28: OPERADOR JUMBO RADIAL | D28: CATALAN PARDO UNGER LUIS | E28: A | F28: L | G28: TAPIA MANCILLA WILDO ALEJANDRO | H28: A | I28: L | J28: FLORES LEON HECTOR MARIO | K28: A | L28: L | M28: VILLALEN HUAIQUILAO IVAN ENRIQUE | N28: A | O28: L | P28: 4 | T28: =SUM(P28:Q28) -> 4
B29: OPERADOR | C29: OPERADOR JUMBO BOLTEC | D29: CEBALLOS BAEZA EMILIANO DE LA CRUZ | E29: A | G29: MORALES BUENO MAXIMILIANO ALEXIS | H29: A | J29: MONSALVE ROJAS JORGE ANTONIO | K29: A | M29: ORELLANA GOMEZ PABLO ANDRES | N29: P | Q29: 4 | R29: 3 | S29: =+COUNTIF(D29:O29,"A")+COUNTIF(D29:O29,"C") -> 3 | T29: =SUM(P29:Q29) -> 4
B30: OPERADOR | C30: OPERADOR SCOOP 1 | D30: GALLARDO LEON GUSTAVO ADOLFO | E30: A | F30: L | G30: MUÑOZ AHUMADA JUAN ANGELO | H30: A | I30: L | J30: MORALES PONCE CARLOS ALBERTO | K30: A | N30: V | P30: 4 | T30: =SUM(P30:Q30) -> 4
B31: OPERADOR | C31: OPERADOR SCOOP 2 | D31: CONEJEROS AVILA WILSON ALEJANDRO | E31: A | F31: L | G31: DONOSO ESPINOZA SEBASTIAN OSVALDO | H31: A | I31: L | J31: BARRIOS ROJAS PHILLIPE GUSTAVO | K31: A | L31: L | M31: RAMIREZ VALENCIA VALERIANO ROBERTO | N31: A | O31: L | P31: 4 | T31: =SUM(P31:Q31) -> 4
B32: OPERADOR | C32: OPERADOR ROBOSHOT 1 | D32: FUENTEALBA CORREA ERNESTO IVAN | E32: A | F32: L | G32: URBINA POBLETE CRISTIAN MAURICIO(PASA A OPÉRADOR DE ROBOSHOT) | H32: A | I32: L | J32: VALDIVIA GONZALEZ LUIS | K32: A | L32: L | M32: ABARCA AGUIRRE MIGUEL ANGEL | N32: A | P32: 4 | T32: =SUM(P32:Q32) -> 4
B33: OPERADOR | C33: OPERADOR ROBOSHOT 2 | D33: SOTO ARRUE SERGIO ANTONIO | E33: A | G33: VALENZUELA RIQUELME JUAN CARLOS | H33: A | I33: L | J33: LOPEZ DURAN RODRIGO ANDRES | K33: A | M33: CHAVEZ POZO HECTOR RODRIGO | N33: A | Q33: 4 | R33: 4 | S33: =+COUNTIF(D33:O33,"A")+COUNTIF(D33:O33,"C") -> 4 | T33: =SUM(P33:Q33) -> 4
B34: OPERADOR | C34: OPERADOR RETROEXCAVADORA - ACUÑADOR | D34: IBARRA MONSALVE CESAR ANTONIO | E34: A | F34: L | G34: CLAUDIO HERNAN TAPIA CAMPOS | H34: A | J34: QUIROZ LOPEZ GERARDO SEBASTIAN | K34: A | L34: L | M34: ARANGUIZ ARANGUIZ MARCO ANTONIO | N34: A | P34: 4 | T34: =SUM(P34:Q34) -> 4
B35: OPERADOR | C35: OPERADOR RETROEXCAVADORA - ACUÑADOR | E35: V | H35: V | J35: VIDAL PAVEZ BASTIAN ALEXIS | K35: A | L35: L | M35: ROJAS PEREZ RICARDO ESTEBAN | N35: A | P35: 4 | T35: =SUM(P35:Q35) -> 4
B36: OPERADOR | C36: OPERADOR MIXER | D36: DONOSO PARRA JONATHAN ANDRES | E36: C | H36: V | J36: CARQUIN MALDONADO CRISTIAN PASCUAL | K36: A | M36: GOMEZ ARANGUIZ JORGE ENRIQUE | N36: C | Q36: 4 | R36: 1 | S36: =+COUNTIF(D36:O36,"A")+COUNTIF(D36:O36,"C") -> 3 | T36: =SUM(P36:Q36) -> 4
B37: OPERADOR | C37: OPERADOR MIXER | D37: MONTECINOS MEZA FERNANDO NICOLAS ALONSO | E37: P | H37: V | K37: V | N37: V | Q37: 4 | S37: =+COUNTIF(D37:O37,"A")+COUNTIF(D37:O37,"C") -> 0 | T37: =SUM(P37:Q37) -> 4
B38: OPERADOR | C38: OPERADOR BROKK | E38: V | H38: V | K38: V | N38: V | Q38: 4 | S38: =+COUNTIF(D38:O38,"A")+COUNTIF(D38:O38,"C") -> 0 | T38: =SUM(P38:Q38) -> 4
C39: CUADRILLA 1 | T39: =SUM(P39:Q39) -> 0
B40: OPERACIÓN | C40: CAPATAZ MINERÍA - OOCC | D40: BERROCAL AGUILAR JOSE RUBEN | E40: A | G40: DONOSO GONZALEZ ARMANDO | H40: A | J40: DIAZ HERNANDEZ MIGUEL EMILIO | K40: C | M40: RAMIREZ CERDA LUIS ALBERTO | N40: A | P40: 4 | T40: =SUM(P40:Q40) -> 4
B41: OPERACIÓN | C41: MAESTRO M1 | D41: ESCOBAR ESCOBAR JUAN CARLOS | E41: A | G41: VIVANCO ABARCA CRISTIAN ALEJANDRO | H41: A | J41: CASTILLO PARRA JOSE MANUEL (M1 OOCC) | K41: A | M41: MANRIQUEZ MARTINEZ ABELINO AMADOR | N41: A | P41: 4 | T41: =SUM(P41:Q41) -> 4
...

Sheet MANO DE OBRA
B2: ADMINISTRADOR | C2: ADMINISTRADOR | D2: 5X2 | E2: HUENCHUMÁN LÓPEZ ALAN FABIÁN ANDRÉS | N2: A
B3: DEPARTAMENTO | C3: CARGO | D3: Turno | E3: GRUPO 1 | F3: EST G1 | G3: GRUPO 2 | H3: EST G2 | I3: LIC G2 | J3: GRUPO 3 | K3: EST G3 | L3: LIC G3 | M3: GRUPO 4 | N3: EST G4 | O3: BASE | P3: ODS1 | Q3: OK | R3: DOT. TOTAL
A4: 1 | C4: SUPERVISIÓN
B5: OPERACIÓN | C5: JEFE DE TURNO 1 | D5: 7x7 | E5: DROGUETT MUÑOZ MARCOS ANTONIO | F5: A | G5: ALDUNCE DEVIA MIGUEL ANGEL | H5: A | I5: L | J5: URZUA DELGADO RODRIGO ISMAEL | K5: A | M5: HORMAZABAL SOTO HERNAN ENRIQUE | N5: A | O5: 4 | R5: =SUM(O5:P5) -> 4
A6: 1 | B6: OPERACIÓN | C6: JEFE DE TURNO 2 | D6: 7x7 | E6: REUSSIER MANRIQUEZ OMAR JAMPIER | F6: A | G6: LEIVA BECERRA JAVIER ANTONIO | H6: A | J6: GARRIDO CASTILLO CRISTOFER NIVALDO | K6: A | L6: L | M6: REYES JOHNSON CLAUDIO ANDRÉS | N6: A | P6: 4 | Q6: =+COUNTIF(E6:N6,"A")+COUNTIF(E6:N6,"C") -> 4 | R6: =SUM(O6:P6) -> 4 | U6: Puestos adicionales por Ampliacion
B7: PREVENCION | C7: APR 1 | D7: 7x7 | E7: ROJAS HERNANDEZ MARIO ANIBAL | F7: A | G7: OPAZO PALMA KAREN GRACIELA | H7: A | J7: INZUNZA ÓRDENES SANTIAGO ABRAHAM | K7: A | M7: POBLETE RODRIGO PEREZ | N7: A | O7: 4 | R7: =SUM(O7:P7) -> 4 | U7: Vacantes disponibles contrato actual
A8: 1 | B8: PREVENCION | C8: APR 2 | D8: 7x7 | E8: MUÑOZ SAN MARTIN RODRIGO ESTEBAN | F8: A | G8: PACHECO HERRERA PABLO | H8: A | J8: CASTILLO GONZALEZ RAUL RENE | K8: A | M8: ORDENES ROJAS JUAN ENRIQUE | N8: A | P8: 4 | Q8: =+COUNTIF(E8:N8,"A")+COUNTIF(E8:N8,"C") -> 4 | R8: =SUM(O8:P8) -> 4
B9: OF. TECNICA | C9: SALA CONTROL | D9: 7x7 | E9: SALAZAR RODRIGUEZ CARLOS ALBERTO | F9: A | G9: ARRIAZA VIDAL MARTIN ENRIQUE | H9: A | J9: COLOMA TOLEDO ALVARO ALBERTO | K9: A | M9: HENRIQUEZ ORTIZ MARCELO JAVIER | N9: A | O9: 4 | R9: =SUM(O9:P9) -> 4
A10: 1 | C10: SOPORTE OPERACIÓN | Q10: =+COUNTIF(E10:N10,"A")+COUNTIF(E10:N10,"C") -> 0 | R10: =SUM(O10:P10) -> 0
B11: ELECTRICO | C11: LÍDER ELECTRICISTA | D11: 7x7 | E11: SEGUEL CISTERNA JEAN LESTER | F11: A | G11: PEREZ BOBADILLA LUIS ALEJANDRO | H11: A | J11: SOTO SEVERINO ROBERTO ANTONIO | K11: A | L11: L | M11: GUTIERREZ VALENZUELA CARLOS ANDRES | N11: A | P11: 4 | R11: =SUM(O11:P11) -> 4
B12: ELECTRICO | C12: MAESTRO ELECTRICISTA 1 | D12: 7x7 | E12: RIVERA URRA DIXON ANTONIO | F12: A | G12: FONSECA FARIAS ANGEL DANIEL | H12: A | J12: REYES OCAMPO MARIO RAFAEL | K12: A | M12: CABEZAS DONOSO BASTIAN ANDRES | N12: P | O12: 4 | R12: =SUM(O12:P12) -> 4
B13: ELECTRICO | C13: MAESTRO ELECTRICISTA 2 | D13: 7x7 | E13: SANDOVAL CANTILLANA BRIAN DANIEL | F13: A | G13: MIRANDA REYES CESAR EDUARDO | H13: A | J13: AYALA PINO FERNANDO ANTONIO | K13: A | M13: SANDOVAL CANTILLANA MATIAS NICOLAS | N13: A | O13: 4 | R13: =SUM(O13:P13) -> 4
A14: 1 | B14: ELECTRICO | C14: MAESTRO ELECTRICISTA 3 | D14: 7x7 | E14: GONZALEZ JARA MANUEL ALEJANDRO | F14: A | G14: ROBLES HIDALGO BRYAN | H14: A | J14: GUZMAN ZAMORANO RAUL ANDRES | K14: A | M14: VALDIVIA MENARES SERGIO ANDRES | N14: A | P14: 4 | Q14: =+COUNTIF(E14:N14,"A")+COUNTIF(E14:N14,"C") -> 4 | R14: =SUM(O14:P14) -> 4
A15: 1 | B15: ELECTRICO | C15: ELECTRÓNICO | D15: 7x7 | E15: CARRASCO GUTIERREZ PABLO JAVIER | F15: A | G15: ORTEGA HERRERA JUAN DANIEL | H15: A | J15: LOPEZ BARRAZA ALEXANDER ESTEBAN | K15: A | M15: CARRASCO GUTIERREZ PABLO JAVIER | N15: A | O15: 2 | P15: 2 | Q15: =+COUNTIF(F15:N15,"A")+COUNTIF(F15:N15,"C") -> 4 | R15: =SUM(O15:P15) -> 4
C16: DEPTO MECANICO
A17: 1 | B17: MECANICO | C17: LÍDER MECÁNICO | D17: 7x7 | E17: REYES GONZALEZ JOSE IGNACIO | F17: A | G17: VALDIVIA PEREZ HERNAN ALEJANDRO | H17: A | J17: GONZALEZ CACERES PATRICIO OCTAVIO | K17: A | M17: LOPEZ BUSTAMANTE CARLOS ENRIQUE | N17: A | P17: 4 | Q17: =+COUNTIF(E17:N17,"A")+COUNTIF(E17:N17,"C") -> 4 | R17: =SUM(O17:P17) -> 4
B18: MECANICO | C18: MAESTRO MECÁNICO 1 | D18: 7x7 | E18: REDONDO JIMENEZ FELIPE ANDRES | F18: A | G18: MIRANDA RAMOS JAVIER ALEJANDRO | H18: A | J18: NUÑEZ LEON VICTOR MANUEL | K18: A | M18: FUENTES ORTEGA JESUS ALEJANDRO | N18: A | O18: 4 | R18: =SUM(O18:P18) -> 4
B19: MECANICO | C19: MAESTRO MECÁNICO 2 | D19: 7x7 | E19: SALAZAR FELIPE | F19: A | G19: PARRA VICTOR | H19: A | J19: RUBIO SAEZ JOSE ANTONIO | K19: A | M19: VERGARA AGUILAR JAVIER IGNACIO | N19: A | O19: 4 | R19: =SUM(O19:P19) -> 4
B20: MECANICO | C20: MAESTRO MECÁNICO 3 | D20: 7x7 | E20: VACANTE | F20: V | G20: VAZQUEZ MIRANDA PABLO | H20: A | J20: CRISTOBAL MUÑOZ TERAN | K20: A | M20: MEDINA CORONADO EDSON | N20: A | O20: 4 | R20: =SUM(O20:P20) -> 4
B21: MECANICO | C21: ELECTROMECÁNICO | D21: 7x7 | E21: ABARCA ESPINOZA JUAN JOSE | F21: A | G21: CABEZAS MORENO JUAN CARLOS | H21: A | J21: ALARCÓN PALMA RICARDO | K21: A | M21: MENDEZ RODRIGUEZ JORGE LUIS | N21: A | O21: 4 | R21: =SUM(O21:P21) -> 4
B22: OPERACIÓN | C22: BODEGUERO 1 | D22: 7x7 | E22: NARVÁEZ BÓRQUEZ CHRISTIAN MARCELO | F22: A | G22: TOBAR VERGARA JUAN PABLO | H22: A | J22: CORREA GALDAMES MAURICIO ALFONSO | K22: A | M22: BONET MEDINA JOSÉ | N22: A | O22: 4 | R22: =SUM(O22:P22) -> 4
B23: OPERACIÓN | C23: CHOFER DE SERVICIOS 1 | D23: 7x7 | E23: ARANGUIZ CASTRO JOSE MIGUEL | F23: A | G23: MONSALVE VILLA RODRIGO IGNACIO | H23: A | I23: L | J23: GARCIA ESQUIVEL MAURICIO ANDRES | K23: A | M23: GUAJARDO MIRANDA BRUNO SEBASTIAN | N23: A | O23: 4 | R23: =SUM(O23:P23) -> 4
B24: OPERACIÓN | C24: CHOFER DE SERVICIOS 2 | D24: 7x7 | E24: MELLA CORDERO CRISTIAN ANDRES | F24: P | G24: CARVAJAL AHUMADA JUAN ENRIQUE | H24: A | J24: GAJARDO CORDERO FERNANDO BASTIAN | K24: A | M24: CASTILLO IBÁÑEZ JOSÉ ALFREDO | N24: A | O24: 4 | R24: =SUM(O24:P24) -> 4
B25: OPERACIÓN | C25: CHOFER DE SERVICIOS 3 | D25: 7x7 | E25: MORENO PALMA OSVALDO ENRIQUE | F25: A | G25: PEREZ AVILA SEBASTIAN SAMUEL | H25: A | I25: L | J25: FAUNDEZ ROMERO PATRICIO RICARDO | K25: A | L25: L | M25: URZUA PIÑA ALEJANDRO ESTEBAN | N25: A
B26: OPERACIÓN | C26: CHOFER DE SERVICIOS 4 | D26: 7x7 | E26: BARRERA MOLINA CRISTIAN EDUARDO | F26: A | G26: PEREZ AGUIRRE RENE ALFONSO | H26: A | J26: VARGAS ORREGO PIA FRANCISCA | K26: A | M26: VACANTE | N26: V-CS
A27: 1 | C27: EQUIPOS MINERÍA Y OOCC | Q27: =+COUNTIF(E27:N27,"A")+COUNTIF(E27:N27,"C") -> 0 | R27: =SUM(O27:P27) -> 0
B28: OPERADOR | C28: OPERADOR JUMBO FORTIFICACION 1 | D28: 7x7 | E28: PEREZ YAÑEZ HECTOR EDUARDO | F28: A | G28: OYARCE FAUNDEZ MANUEL ALEJANDRO | H28: P | I28: L | J28: ADASME ROJAS LUIS MAURICIO | K28: A | L28: L | M28: GONZALEZ MORENO FRANCISCO JAVIER | N28: A | O28: 4 | R28: =SUM(O28:P28) -> 4
B29: OPERADOR | C29: OPERADOR JUMBO FORTIFICACION 2 | D29: 7x7 | E29: DIAZ RIVERA RAUL ALEJANDRO | F29: A | G29: HERNANDEZ ESPINOZA JOSE ANTONIO | H29: A | I29: L | J29: GONZALEZ QUISPE MARCO ANDRES | K29: A | L29: L | M29: MORENO MORENO ALEJANDRO ANTONIO | N29: LM | O29: 4 | R29: =SUM(O29:P29) -> 4
A30: 1 | B30: OPERADOR | C30: OPERADOR JUMBO FORTIFICACION 3 | D30: 7x7 | E30: MAUREIRA ROMERO FELIPE ANDRES | F30: A | G30: CARRERA VIDAL JOSE ISAAC | H30: A | J30: HORMAZABAL IBACETA ALEJANDRO DANIEL | K30: A | M30: ROJAS MILLA JOSE LUIS | N30: A | P30: 4 | Q30: =+COUNTIF(E30:N30,"A")+COUNTIF(E30:N30,"C") -> 4 | R30: =SUM(O30:P30) -> 4
B31: OPERADOR | C31: OPERADOR JUMBO RADIAL | D31: 7x7 | E31: CATALAN PARDO UNGER LUIS | F31: A | G31: TAPIA MANCILLA WILDO ALEJANDRO | H31: A | I31: L | J31: FLORES LEON HECTOR MARIO | K31: A | L31: L | M31: VILLALEN HUAIQUILAO IVAN ENRIQUE | N31: A | O31: 4 | R31: =SUM(O31:P31) -> 4
A32: 1 | B32: OPERADOR | C32: OPERADOR JUMBO BOLTEC | D32: 7x7 | E32: ORELLENA GOMEZ PABLO | F32: A | G32: MORALES BUENO MAXIMILIANO ALEXIS | H32: A | J32: MONSALVE ROJAS JORGE ANTONIO | K32: A | M32: FREDES MOLINA VICTOR EDUARDO | N32: A | P32: 4 | Q32: =+COUNTIF(E32:N32,"A")+COUNTIF(E32:N32,"C") -> 4 | R32: =SUM(O32:P32) -> 4
B33: OPERADOR | C33: OPERADOR SCOOP 1 | D33: 7x7 | E33: IBARRA MONSALVE CESAR ANTONIO | F33: A | G33: MUÑOZ AHUMADA JUAN ANGELO | H33: A | I33: L | J33: CARRASCO CERDA CARLOS ALBERTO | K33: A | M33: CABEZAS VILLAGRA FERNANDO ANTONIO | N33: A | O33: 4 | R33: =SUM(O33:P33) -> 4
B34: OPERADOR | C34: OPERADOR SCOOP 2 | D34: 7x7 | E34: HONDARZA SAEZ BENJAMIN MATIAS | F34: A | G34: DONOSO ESPINOZA SEBASTIAN OSVALDO | H34: A | I34: L | J34: YAÑEZ VILLAGRAN RICARDO ANTONIO | K34: A | M34: RAMIREZ VALENCIA VALERIANO ROBERTO | N34: A | O34: 4 | R34: =SUM(O34:P34) -> 4
B35: OPERADOR | C35: OPERADOR ROBOSHOT 1 | D35: 7x7 | E35: FUENTEALBA CORREA ERNESTO IVAN | F35: A | G35: URBINA POBLETE CRISTIAN MAURICIO | H35: A | I35: L | J35: VALDIVIA GONZALEZ LUIS | K35: A | L35: L | M35: ABARCA AGUIRRE MIGUEL ANGEL | N35: A | O35: 4 | R35: =SUM(O35:P35) -> 4
A36: 1 | B36: OPERADOR | C36: OPERADOR ROBOSHOT 2 | D36: 7x7 | E36: SOTO ARRUE SERGIO ANTONIO | F36: A | G36: VALENZUELA RIQUELME JUAN CARLOS | H36: A | I36: L | J36: LOPEZ DURAN RODRIGO ANDRES | K36: A | M36: CHAVEZ POZO HECTOR RODRIGO | N36: A | P36: 4 | Q36: =+COUNTIF(E36:N36,"A")+COUNTIF(E36:N36,"C") -> 4 | R36: =SUM(O36:P36) -> 4
B37: OPERADOR | C37: OPERADOR RETROEXCAVADORA - ACUÑADOR | D37: 7x7 | E37: LILLO CASTRO JUAN SEGUNDO | F37: P | G37: MOLINA PINCHEIRA BENITO ANDRES | H37: A | J37: MONTERO CORTEZ ABRAHAM RICARDO | K37: A | M37: GUZMAN MATURANA CESAR ANTONIO | N37: A | O37: 4 | R37: =SUM(O37:P37) -> 4
B38: OPERADOR | C38: OPERADOR RETROEXCAVADORA - ACUÑADOR | D38: 7x7 | E38: FUENTES CANIO DARIO JOSE | F38: P | G38: VALENZUELA CONTRERAS JOEL JARED | H38: A | J38: NUÑEZ VALENZUELA LUIS | K38: P | M38: NUÑEZ VALENZELA ARMANDO | N38: P | O38: 4 | R38: =SUM(O38:P38) -> 4
A39: 1 | B39: OPERADOR | C39: OPERADOR MIXER | D39: 7x7 | E39: VACANTE | F39: V-MIX | G39: VACANTE | H39: V-MIX | J39: GOMEZ ARANGUIZ JORGE ENRIQUE | K39: A | M39: CARQUIN MALDONADO CRISTIAN PASCUAL | N39: A | P39: 4 | Q39: =+COUNTIF(E39:N39,"A")+COUNTIF(E39:N39,"C") -> 2 | R39: =SUM(O39:P39) -> 4
A40: 1 | B40: OPERADOR | C40: OPERADOR MIXER | D40: 7x7 | E40: GALAZ ARAVENA RAUL ERNESTO | F40: A | G40: BAU MERIÑO MARCO ANTONIO | H40: A | J40: NAVARRO VARGAS LEONARDO ARTURO | K40: A | M40: RAMIREZ DIAZ EDUARDO CARLOS | N40: A | P40: 4 | Q40: =+COUNTIF(E40:N40,"A")+COUNTIF(E40:N40,"C") -> 4 | R40: =SUM(O40:P40) -> 4
A41: 1 | B41: OPERADOR | C41: OPERADOR BROKK | D41: 7x7 | E41: VACANTE | F41: V-BR | G41: HERNANDEZ SALINAS EDUARDO MARCELO | H41: P | J41: VACANTE | K41: V-BR | M41: VACANTE | N41: V-BR | R41: =SUM(O41:P41) -> 0
...

Sheet RESUMEN
D12: ESTATUS | E12: G1 | F12: G2 | G12: G3 | H12: G4 | I12: 7x7 T°A - 5x2 | J12: OTROS | K12: TOTAL
D13: ACREDITADOS | E13: =#REF! -> #REF! | F13: =#REF! -> #REF! | G13: =#REF! -> #REF! | H13: =#REF! -> #REF! | I13: =#REF! -> #REF! | K13: =SUM(E13:J13) -> #REF!
D14: PENDIENTE APROBACIÓN SUCAL | E14: =#REF! -> #REF! | F14: =#REF! -> #REF! | G14: =#REF! -> #REF! | H14: =#REF! -> #REF! | I14: =#REF! -> #REF! | K14: =SUM(E14:J14) -> #REF!
D15: CONTRATADOS SIN ACREDITAR | E15: =#REF! -> #REF! | F15: =#REF! -> #REF! | G15: =#REF! -> #REF! | H15: =#REF! -> #REF! | I15: =#REF! -> #REF! | K15: =SUM(E15:J15) -> #REF!
D16: EN PROCESO DE CONTRATACIÓN | E16: =#REF! -> #REF! | F16: =#REF! -> #REF! | G16: =#REF! -> #REF! | H16: =#REF! -> #REF! | I16: =#REF! -> #REF! | K16: =SUM(E16:J16) -> #REF!
D17: VACANTES | E17: =#REF! -> #REF! | F17: =#REF! -> #REF! | G17: =#REF! -> #REF! | H17: =#REF! -> #REF! | I17: =#REF! -> #REF! | K17: =SUM(E17:J17) -> #REF!
D18: SINDICATO, LM Y PRÁCTICAS | J18: ='Sindicato y LM'!D16 -> 10 | K18: =SUM(E18:J18) -> 10
D20: TOTAL A CUBRIR | E20: =+SUM(E13:E18) -> #REF! | F20: =+SUM(F13:F18) -> #REF! | G20: =+SUM(G13:G18) -> #REF! | H20: =+SUM(H13:H18) -> #REF! | I20: =+SUM(I13:I18) -> #REF! | J20: =+SUM(J13:J18) -> 10 | K20: =SUM(K13:K18) -> #REF!
D21: CUMPLIMINETO POR GRUPO | E21: =+(E13+E14+E15)/E20 -> #REF! | F21: =+(F13+F14+F15)/F20 -> #REF! | G21: =+(G13+G14+G15)/G20 -> #REF! | H21: =+(H13+H14+H15)/H20 -> #REF! | I21: =+(I13+I14+I15)/I20 -> #REF!
D23: CUADRILLAS | E23: 13 | F23: 13 | G23: 13 | H23: 13
D25: CONTRATADOS AL 26-01 | E25: =K13+K14+K15+K18 -> #REF!
D26: CUMPLIMINETO GLOBAL | E26: =+E25/K20 -> #REF!

Sheet Hoja2
A3: Etiquetas de fila | B3: Cuenta de NOMBRE
A4: ABARCA AGUIRRE MIGUEL ANGEL | B4: 1 | D4: ABARCA
A5: ABARCA ESPINOZA JUAN JOSE | B5: 1 | D5: ABARCA
A6: ABARCA PALMA BRUNO ALEJADRNO | B6: 1 | D6: ABARCA
A7: ABARCA PEREZ JORGE ANTONIO (SOLDADOR) | B7: 1 | D7: ABARCA
A8: ACEITUNO REYES CRISTOBAL ANTONIO (5X2) | B8: 1 | D8: ACEITUNO
A9: ACEVEDO OSORIO JULIO FERNANDO | B9: 1
A10: ADASME ROJAS LUIS MAURICIO | B10: 1 | D10: ADASME
A11: AGURTO CUADRA LUIS DANIEL | B11: 1 | D11: AGURTO
A12: AHUMADA GUZMAN LEONARDO ENRIQUE | B12: 1 | D12: AHUMADA
A13: ALAMOS DIAZ SERGIO ISMAEL | B13: 1 | D13: ALAMOS
A14: ALARCON LOBOS MAURICIO ALEJANDRO | B14: 1 | D14: ALARCON
A15: ALARCÓN PALMA RICARDO | B15: 1 | D15: ALARCON
A16: ALBIÑA VICENTE | B16: 1 | D16: ALBIÑA
A17: ALBORNOZ ALBORNOZ PABLO ANTONIO | B17: 1 | D17: ALBORNOZ
A18: ALDUNCE DEVIA MIGUEL ANGEL | B18: 1 | D18: ALDUNCE
A19: ALLENDE ROBLES JAVIER FRANCISCO | B19: 1 | D19: ALLENDE
A20: ALVARADO RAMIREZ NICKOL STEPHANY | B20: 1 | D20: ALVARADO
A21: ALVARADO ZUÑIGA JAVIERA IGNACIA | B21: 1 | D21: ALVARADO
... A29: ARAYA BERRIOS DIEGO IGNACIO | B29: 1 | D29: ARAYA
A30: ARAYA SALINAS ESTEBAN ANDRES | B30: 1
A31: ARCE ARCE HUGO HERNAN | B31: 1 | D31: ARCE
A32: ARCE SALAS CARLOS ALBERTO | B32: 1 | D32: ARCE
A33: ARREDONDO CARREÑO OSCAR ENRIQUE | B33: 1 | D33: ARREDONDO
A34: ARREDONDO GONZALEZ LUIS ANTONIO | B34: 1 | D34: ARREDONDO
A35: ARRIAZA VIDAL MARTIN ENRIQUE | B35: 1 | D35: ARRIAZA
A36: ARROYO LOBOS EDUARDO ENRIQUE | B36: 1 | D36: ARROYO
A37: ASTORGA CASTRO AARON BRANDON | B37: 1 | D37: ASTORGA
A38: ASTUDILLO TORO FRANCISCO JAVIER | B38: 1 | D38: ASTUDILLO
A39: AYALA PINO FERNANDO ANTONIO | B39: 1 | D39: AYALA
A40: BAEZA VERGARA JUAN MANUEL | B40: 1 | D40: BAEZA
A41: BARRERA CASTRO SEBASTIÁN DEL CARMEN | B41: 1 | D41: BARRERA
A42: BARRIOS ROJAS PHILLIPE GUSTAVO | B42: 1 | D42: BARRIOS
A43: BASULTO ADASME LEONARDO ALONSO | B43: 1 | D43: BASULTO
A44: BECERRA FERNANDEZ DIEGO MATIAS | B44: 1
A45: BECERRA RIVEROS JUAN PATRICIO | B45: 1 | D45: BECERRA
A46: BERRIOS GALAZ ROBERTO | B46: 1 | D46: BERRIOS
A47: BERROCAL AGUILAR JOSE RUBEN | B47: 1 | D47: BERROCAL
A48: BLANCO MARQUEZ PIERO ENRIQUE | B48: 1 | D48: BLANCO
A49: BONET MEDINA JOSÉ | B49: 1 | D49: BONET
...

Sheet Hoja4
A3: Etiquetas de fila | B3: Cuenta de CARGO
A4: AYUDANTE | B4: 2
A5: CHOFER CAMIÓN | B5: 1
A6: ELECTROMECÁNICO | B6: 1
A7: MAESTRO ELECTRICISTA | B7: 2
A8: MAESTRO M1 | B8: 4
A9: MAESTRO MECÁNICO | B9: 2
A10: MECÁNICO ESPECIALISTA | B10: 2
A11: OPERADOR DE EQUIPO DE LEVANTE | B11: 9
A12: OPERADOR JUMBO | B12: 2
A13: OPERADOR MIXER | B13: 3
A14: OPERADOR RETROEXCAVADORA | B14: 1
A15: SOLDADOR | B15: 3
... A17: Total general | B17: 33

Sheet Personal en Proceso a Contratar
B1: CARGO 1 | C1: CARGO | D1: NOMBRE
A2: 1 | B2: OPERADOR JUMBO FORTIFICACION 2 | C2: OPERADOR JUMBO | D2: CARRERA VIDAL JOSE ISAAC
A3: 2 | B3: OPERADOR RETROEXCAVADORA - ACUÑADOR | C3: OPERADOR RETROEXCAVADORA | D3: GONZALEZ FERRADA OSCAR ALEJANDRO
A4: 3 | B4: OPERADOR MIXER | C4: OPERADOR MIXER | D4: GALAZ ARAVENA RAUL ERNESTO
A5: 4 | B5: OPERADOR DE EQUIPO DE LEVANTE | C5: OPERADOR DE EQUIPO DE LEVANTE | D5: MOLINA PINCHEIRA BENITO ANDRES (EN PROCESO)
A6: 5 | B6: MAESTRO M1 | C6: MAESTRO M1 | D6: CEPEDA BADILLA FELICIANO ALEJANDRO(EN PROCESO)
A7: 6 | B7: SOLDADOR | C7: SOLDADOR | D7: VASQUEZ TOLERO LUIS EDUARDO
A8: 7 | B8: SOLDADOR | C8: SOLDADOR | D8: DIAZ LARA JUAN ROBERTO
A9: 8 | B9: MAESTRO MECÁNICO 4 G1-G2 | C9: MAESTRO MECÁNICO | D9: MARCHANT RAMIREZ EDUARDO ANTONIO
A10: 9 | B10: MAESTRO MECÁNICO 4 G3-G4 | C10: MAESTRO MECÁNICO | D10: RIQUELME OVANDO MAIQUEL JONATHAN
A11: 10 | B11: MECÁNICO ESPECIALISTA G1-G2 | C11: MECÁNICO ESPECIALISTA | D11: ESCOBAR MARQUEZ LEONARDO FELIPE
A12: 11 | B12: MECÁNICO ESPECIALISTA G3-G4 | C12: MECÁNICO ESPECIALISTA | D12: JARA BARRIOS ROBERTO SEBASTIAN
A13: 12 | B13: ELECTROMECÁNICO G1-G2 | C13: ELECTROMECÁNICO | D13: RIQUELME CARRASCO CLAUDIO
... A34: 33 | B34: OPERADOR DE EQUIPO DE LEVANTE | C34: OPERADOR DE EQUIPO DE LEVANTE | D34: REMEDY VILLALÓN SEBASTIÁN ADOLFO

Sheet Modificacion MO 
C3: Cargo Actual | D3: Nombre Completo | E3: Cargo Futuro | G3: NOMBRE ACTUAL | H3: CARGO | I3: NOMBRE FUTURO

Sheet Sindicato y LM
B2: SINDICATO
A3: =ROW(C3)-2 -> 1 | B3: CHOFER DE SERVICIOS | C3: MARQUEZ SANCHEZ MANUEL | D3: 1 | E3: SIND
A4: =ROW(C4)-2 -> 2 | B4: CHOFER DE SERVICIOS | C4: PEREZ ZAMORANO FRANCISCO | D4: 1 | E4: SIND
A5: =ROW(C5)-2 -> 3 | B5: CHOFER DE SERVICIOS | C5: RAMOS ROJAS ÁLVARO | D5: 1 | E5: SIND
A6: =ROW(C6)-2 -> 4 | B6: OP.ROBOSHOT G3 | C6: VIDAL PAVEZ BASTIAN ALEXIS | D6: 1 | E6: LM
A7: =ROW(C7)-2 -> 5 | B7: CAPATAZ MONTAJE G2 | C7: MOLINA CONTRERAS JUAN CARLOS | D7: 1 | E7: LM
A8: =ROW(C8)-2 -> 6 | B8: CAPATAZ | C8: SEPULVEDA OVIEDO JHON ANDRES | D8: 1 | E8: LM
A9: =ROW(C9)-2 -> 7 | B9: SOLDADOR | C9: ARAVENA BERRIOS PATRICIO EUGENIO | D9: 1 | E9: LM
A10: =ROW(C10)-2 -> 8 | B10: OP SCOOP | C10: MATURANA ARANGUIZ LUIS ROBERTO | D10: 1 | E10: LM
A11: =ROW(C11)-2 -> 9 | B11: MINERO | C11: CURIN CATRIPAN VICTOR RUBEN | D11: 1 | E11: LM
A12: =ROW(C12)-2 -> 10 | B12: OP GRUA- RETRO | C12: ROJAS PEREZ RICARDO ESTEBAN | D12: 1 | E12: LM
B13: OTROS
B16: TOTAL | D16: =SUM(D3:D13) -> 10

Sheet Detalle
B3: Etiquetas de fila | C3: Cuenta de GRUPO 1 | F3: Etiquetas de fila | G3: Cuenta de GRUPO 2 | I3: Etiquetas de fila | J3: Cuenta de GRUPO 3 | L3: Etiquetas de fila | M3: Cuenta de GRUPO 4
B4: ELECTRICO | C4: 5 | F4: ELECTRICO | G4: =+G5+G9+G11 -> 5 | I4: ELECTRICO | J4: 5 | L4: ELECTRICO | M4: =+M5+M9+M11 -> 5
B5: A | C5: 5 | F5: A | G5: 3 | I5: A | J5: 5 | L5: A | M5: 3
B6: ELECTRÓNICO | C6: 1 | F6: LÍDER ELECTRICISTA | G6: 1 | I6: ELECTRÓNICO | J6: 1 | L6: ELECTRÓNICO | M6: 1
B7: LÍDER ELECTRICISTA | C7: 1 | F7: MAESTRO ELECTRICISTA 1 | G7: 1 | I7: LÍDER ELECTRICISTA | J7: 1 | L7: MAESTRO ELECTRICISTA 1 | M7: 1
B8: MAESTRO ELECTRICISTA 1 | C8: 1 | F8: MAESTRO ELECTRICISTA 2 | G8: 1 | I8: MAESTRO ELECTRICISTA 1 | J8: 1 | L8: MAESTRO ELECTRICISTA 2 | M8: 1
B9: MAESTRO ELECTRICISTA 2 | C9: 1 | F9: C | G9: 1 | I9: MAESTRO ELECTRICISTA 2 | J9: 1 | L9: P | M9: 1
B10: MAESTRO ELECTRICISTA 3 | C10: 1 | F10: ELECTRÓNICO | G10: 1 | I10: MAESTRO ELECTRICISTA 3 | J10: 1 | L10: MAESTRO ELECTRICISTA 3 | M10: 1
B11: MECANICO | C11: 5 | F11: V | G11: 1 | I11: MECANICO | J11: 5 | L11: v | M11: 1
B12: A | C12: 5 | F12: MAESTRO ELECTRICISTA 3 | G12: 1 | I12: A | J12: 5 | L12: LIDER ELECTRICISTA | M12: 1
B13: ELECTROMECÁNICO | C13: 1 | F13: MECANICO | G13: 5 | I13: ELECTROMECÁNICO | J13: 1 | L13: MECANICO | M13: 5
B14: LÍDER MECÁNICO | C14: 1 | F14: A | G14: 5 | I14: LÍDER MECÁNICO | J14: 1 | L14: A | M14: 5
B15: MAESTRO MECÁNICO 1 | C15: 1 | F15: ELECTROMECÁNICO | G15: 1 | I15: MAESTRO MECÁNICO 1 | J15: 1 | L15: ELECTROMECÁNICO | M15: 1
B16: MAESTRO MECÁNICO 2 | C16: 1 | F16: LÍDER MECÁNICO | G16: 1 | I16: MAESTRO MECÁNICO 2 | J16: 1 | L16: LÍDER MECÁNICO | M16: 1
... B20: SALA CONTROL | C20: 1 | F20: OFICINA TECNICA | G20: 1 | I20: SALA CONTROL | J20: 1 | L20: OFICINA TECNICA | M20: 1
B21: OPERACIÓN | C21: =+C22+C37+C43+C47 -> 55 | F21: A | G21: 1 | I21: OPERACIÓN | J21: 55 | L21: A | M21: 1
B22: A | C22: 44 | F22: SALA CONTROL | G22: 1 | I22: A | J22: 45 | L22: SALA CONTROL | M22: 1
B23: AYUDANTE | C23: 4 | F23: OPERACIÓN | G23: =+G24+G38+G40+G45 -> 55 | I23: AYUDANTE | J23: 4 | L23: OPERACIÓN | M23: 55
B24: BODEGUERO 1 | C24: 1 | F24: A | G24: 39 | I24: BODEGUERO 1 | J24: 1 | L24: A | M24: 51
B25: CAPATAZ MINERÍA - OOCC | C25: 10 | F25: AYUDANTE | G25: 3 | I25: CAPATAZ MINERÍA - OOCC | J25: 8 | L25: AYUDANTE | M25: 6
B26: CAPATAZ MONTAJE | C26: 1 | F26: BODEGUERO 1 | G26: 1 | I26: CAPATAZ MONTAJE | J26: 1 | L26: BODEGUERO 1 | M26: 1
B27: CHOFER DE SERVICIOS 1 | C27: 1 | F27: CAPATAZ MINERÍA - OOCC | G27: 12 | I27: CHOFER DE SERVICIOS 1 | J27: 1 | L27: CAPATAZ MINERÍA - OOCC | M27: 10
B28: CHOFER DE SERVICIOS 2 | C28: 1 | F28: CAPATAZ MONTAJE | G28: 1 | I28: CHOFER DE SERVICIOS 2 | J28: 1 | L28: CAPATAZ MONTAJE | M28: 1
B29: CHOFER DE SERVICIOS 3 | C29: 1 | F29: CHOFER DE SERVICIOS 1 | G29: 1 | I29: CHOFER DE SERVICIOS 3 | J29: 1 | L29: CHOFER DE SERVICIOS 1 | M29: 1
B30: JEFE DE TURNO 1 | C30: 1 | F30: CHOFER DE SERVICIOS 3 | G30: 1 | I30: JEFE DE TURNO 1 | J30: 1 | L30: CHOFER DE SERVICIOS 2 | M30: 1
B31: JEFE DE TURNO 2 | C31: 1 | F31: JEFE DE TURNO 1 | G31: 1 | I31: JEFE DE TURNO 2 | J31: 1 | L31: CHOFER DE SERVICIOS 3 | M31: 1
B32: MAESTRO M1 | C32: 17 | F32: JEFE DE TURNO 2 | G32: 1 | I32: MAESTRO M1 | J32: 18 | L32: JEFE DE TURNO 1 | M32: 1
B33: MAESTRO MONTAJE 1 | C33: 1 | F33: MAESTRO M1 | G33: 11 | I33: MAESTRO MONTAJE 1 | J33: 1 | L33: MAESTRO M1 | M33: 21
B34: MAESTRO MONTAJE 2 | C34: 1 | F34: MAESTRO MONTAJE 1 | G34: 1 | I34: MAESTRO MONTAJE 2 | J34: 1 | L34: MAESTRO MONTAJE 1 | M34: 1
B35: SOLDADOR | C35: 3 | F35: MAESTRO MONTAJE 2 | G35: 1 | I35: SOLDADOR | J35: 4 | L35: MAESTRO MONTAJE 2 | M35: 1
... B43: P | C43: 4 | F43: MAESTRO M1 | G43: 7 | I43: MAESTRO M1 | J43: 3 | L43: MAESTRO M1 | M43: 1
B44: AYUDANTE | C44: 1 | F44: SOLDADOR MONTAJE | G44: 1 | I44: OPERADOR | J44: =+J45+J57+J59+J61 -> 26 | L44: OPERADOR | M44: =+M45+M54+M57+M60 -> 26
B45: CAPATAZ MINERÍA - OOCC | C45: 1 | F45: V | G45: 2 | I45: A | J45: 18 | L45: A | M45: 14
B46: MAESTRO M1 | C46: 2 | F46: MAESTRO M1 | G46: 2 | I46: OPERADOR DE EQUIPO DE LEVANTE | J46: 7 | L46: OPERADOR DE EQUIPO DE LEVANTE | M46: 6
B47: V | C47: 1 | F47: OPERADOR | G47: =+G48+G59+G61+G63 -> 25 | I47: OPERADOR JUMBO BOLTEC | J47: 1 | L47: OPERADOR JUMBO FORTIFICACION 1 | M47: 1
B48: MAESTRO M1 | C48: 1 | F48: A | G48: 20 | I48: OPERADOR JUMBO FORTIFICACION 1 | J48: 1 | L48: OPERADOR JUMBO FORTIFICACION 2 | M48: 1
B49: OPERADOR | C49: =+C50+C62+C64+C67 -> 25 | F49: OPERADOR DE EQUIPO DE LEVANTE | G49: 11 | I49: OPERADOR JUMBO FORTIFICACION 2 | J49: 1 | L49: OPERADOR JUMBO RADIAL | M49: 1
B50: A | C50: 19 | F50: OPERADOR JUMBO BOLTEC | G50: 1 | I50: OPERADOR JUMBO RADIAL | J50: 1 | L50: OPERADOR RETROEXCAVADORA - ACUÑADOR | M50: 2
B51: OPERADOR DE EQUIPO DE LEVANTE | C51: 9 | F51: OPERADOR JUMBO FORTIFICACION 1 | G51: 1 | I51: OPERADOR MIXER | J51: 1 | L51: OPERADOR ROBOSHOT 1 | M51: 1
B52: OPERADOR JUMBO BOLTEC | C52: 1 | F52: OPERADOR JUMBO FORTIFICACION 2 | G52: 1 | I52: OPERADOR RETROEXCAVADORA - ACUÑADOR | J52: 2 | L52: OPERADOR ROBOSHOT 2 | M52: 1
...

Sheet Vacantes
C4: ELECTRICO | D4: 1
B5: Grupo 4 | C5: V | D5: 1 | G5: OPERADOR | H5: =+H6+H8+H12+H16+H20 -> 9
C6: Maestro Electricista 1 | D6: 1 | F6: Grupo 1 | G6: V | H6: 1
G7: OPERADOR RETROEXCAVADORA - ACUÑADOR | H7: 1
F8: Grupo 2 | G8: V | H8: 1
G9: OPERADOR RETROEXCAVADORA - ACUÑADOR | H9: 1
C10: OPERACIÓN | D10: =+D11+D13+D15 -> 4 | G10: V | H10: 2
B11: Grupo 1 | C11: V | D11: 1 | G11: OPERADOR DE EQUIPO DE LEVANTE | H11: 2
C12: MAESTRO M1 | D12: 1 | F12: Grupo 3 | G12: V | H12: 3
B13: Grupo 2 | C13: V | D13: 2 | G13: OPERADOR BROKK | H13: 1
C14: MAESTRO M1 | D14: 2 | G14: OPERADOR DE EQUIPO DE LEVANTE | H14: 1
B15: 5x2 | C15: V | D15: 1 | G15: OPERADOR MIXER | H15: 1
C16: AYUDANTE MISCELÁNEOS | D16: 1 | F16: Grupo 4 | G16: v | H16: 3
G17: OPERADOR BROKK | H17: 1
G18: OPERADOR MIXER | H18: 1
G19: OPERADOR SCOOP 1 | H19: 1
F20: Soporte 7x7 TA | G20: V | H20: 1
C21: MECANICO | D21: 2 | G21: CHOFER CAMIÓN TOLVA G3 - G4 | H21: 1
C22: V | D22: 2
B23: Soporte 7x7 TA | C23: ELECTROMECÁNICO G1-G2 | D23: 1
C24: MECÁNICO ESPECIALISTA G1-G2 | D24: 1

Sheet Dinamica Grupos
A3: Etiquetas de fila | B3: Cuenta de GRUPO 1
A4: ELECTRICO | B4: 5
A5: A | B5: 5
A6: ELECTRÓNICO | B6: 1
A7: LÍDER ELECTRICISTA | B7: 1
A8: MAESTRO ELECTRICISTA 1 | B8: 1
A9: MAESTRO ELECTRICISTA 2 | B9: 1
A10: MAESTRO ELECTRICISTA 3 | B10: 1
A11: MECANICO | B11: 5
A12: A | B12: 5
A13: ELECTROMECÁNICO | B13: 1
A14: LÍDER MECÁNICO | B14: 1
A15: MAESTRO MECÁNICO 1 | B15: 1
... A35: CAPATAZ MINERÍA - OOCC | B35: 1
A36: V
A37: MAESTRO M1
A38: OPERADOR | B38: 24
A39: A | B39: 21
A40: OPERADOR DE EQUIPO DE LEVANTE | B40: 10
A41: OPERADOR JUMBO BOLTEC | B41: 1
A42: OPERADOR JUMBO FORTIFICACION 1 | B42: 1
A43: OPERADOR JUMBO FORTIFICACION 2 | B43: 1
A44: OPERADOR JUMBO FORTIFICACION 3 | B44: 1
A45: OPERADOR JUMBO RADIAL | B45: 1
A46: OPERADOR MIXER | B46: 1
A47: OPERADOR RETROEXCAVADORA - ACUÑADOR | B47: 1
A48: OPERADOR ROBOSHOT 1 | B48: 1
A49: OPERADOR ROBOSHOT 2 | B49: 1
... A54: OPERADOR RETROEXCAVADORA - ACUÑADOR | B54: 1
A55: V
A56: OPERADOR MIXER
A57: (en blanco)
A58: OPERADOR BROKK
A59: (en blanco)
A60: (en blanco)
A61: CUADRILLA 1
A62: CUADRILLA 10
A63: CUADRILLA 11
A64: CUADRILLA 12
A65: CUADRILLA 2
...

Sheet Dinamica 7x7TA
A3: Etiquetas de fila | B3: Cuenta de SOPORTE OPERACIÓN 7x7 T°A
A4: MECANICO | B4: 7
A5: A | B5: 2
A6: ELECTROMECÁNICO G3-G4 | B6: 1
A7: MECÁNICO MANTENCIÓN G1-G2 | B7: 1
A8: P | B8: 5
A9: MAESTRO MECÁNICO 4 G1-G2 | B9: 1
A10: MAESTRO MECÁNICO 4 G3-G4 | B10: 1
A11: MECÁNICO ESPECIALISTA G1-G2 | B11: 1
A12: MECÁNICO ESPECIALISTA G3-G4 | B12: 1
A13: MECÁNICO MANTENCIÓN G3-G4 | B13: 1
A14: V
A15: ELECTROMECÁNICO G1-G2
A16: OPERACIÓN | B16: 6
A17: A | B17: 6
A18: SOLDADOR MANTENCIÓN G1-G2 | B18: 1
A19: SOLDADOR MANTENCIÓN G3-G4 | B19: 1
A20: VULCANIZADOR G1-G2 | B20: 1
A21: VULCANIZADOR G3-G4 | B21: 1
A22: CAPATAZ 7X7 TA G1 -G2 | B22: 2
A23: OPERADOR | B23: 5
A24: A | B24: 5
A25: CHOFER CAMIÓN PLANO 1 G1-G2 | B25: 1
A26: CHOFER CAMIÓN PLANO 1 G2-G3 | B26: 1
A27: CHOFER CAMIÓN PLANO 2 G1-G2 | B27: 1
... A29: CHOFER CAMIÓN TOLVA G1-G2 | B29: 1
A30: V
A31: CHOFER CAMIÓN TOLVA G3 - G4
A32: Total general | B32: 18

Sheet Dinamica 5x2 TA
A3: Etiquetas de fila | B3: Cuenta de SOPORTE OPERACIÓN 5x2
A4: OPERACIÓN | B4: 6
A5: A | B5: 6
A6: CAPATAZ MISCELÁNEOS | B6: 1
A7: INSTRUCTOR BOLTEC | B7: 1
A8: MAESTRO AVANZADO MISCELÁNEOS | B8: 1
A9: MAESTRO OOCC MISCELÁNEOS | B9: 1
A10: SOLDADOR MONTAJE MISCELÁNEOS | B10: 1
A11: SUPERVISOR MONTAJE | B11: 1
A12: V
A13: AYUDANTE MISCELÁNEOS
A14: OPERADOR | B14: 1
A15: A | B15: 1
A16: CHOFER CAMIÓN TOLVA 2 | B16: 1
A17: V
A18: CHOFER CAMIÓN PLANO 3
A19: Total general | B19: 7

Sheet Dotación Ampliación
B2: CARGO | C2: ECO05 | D2: ODS N°1 | E2: TOTAL
B3: JEFE DE TURNO | C3: 4 | D3: 4 | E3: =C3+D3 -> 8
B4: PREVENCIONISTA DE TURNO | C4: 4 | D4: 4 | E4: =C4+D4 -> 8
B5: INGENIERO SALA DE CONTROL | C5: 4 | D5: 0 | E5: =C5+D5 -> 4
B6: LIDER ELECTRICISTA | C6: 0 | D6: 4 | E6: =C6+D6 -> 4
B7: MAESTRO ELECTRICISTAS | C7: 8 | D7: 4 | E7: =C7+D7 -> 12
B8: ELECTRONICO | C8: 2 | D8: 2 | E8: =C8+D8 -> 4
B9: LIDER MECÁNICO | C9: 0 | D9: 4 | E9: =C9+D9 -> 4
B10: MAESTRO MECANICO | C10: 12 | D10: 2 | E10: =C10+D10 -> 14
B11: MECÁNICO ESPECIALISTA | C11: 0 | D11: 2 | E11: =C11+D11 -> 2
B12: MECANICO MANTENCIÓN | C12: 0 | D12: 2 | E12: =C12+D12 -> 2
B13: VULCANIZADOR | C13: 1 | D13: 0 | E13: =C13+D13 -> 1
B14: SOLDADOR MANTENCION | C14: 2 | D14: 0 | E14: =C14+D14 -> 2
... B26: OPERADOR SCOOP | C26: 8 | D26: 0 | E26: =C26+D26 -> 8
B27: OPERADOR ROBOSHOT | C27: 4 | D27: 4 | E27: =C27+D27 -> 8 | J27: |
B28: OPERADOR RETROEXCAVADORA - ACUÑADOR | C28: 8 | D28: 0 | E28: =C28+D28 -> 8
B29: OPERADOR MIXER | C29: 0 | D29: 8 | E29: =C29+D29 -> 8
B30: OPERADOR BROKK | C30: 0 | D30: 4 | E30: =C30+D30 -> 4
B31: OPERADOR EQUIPO LEVANTE/ MINI CARGADOR | C31: 32 | D31: 16 | E31: =C31+D31 -> 48
B32: CAPATAZ MINERIA - OOCC | C32: 32 | D32: 16 | E32: =C32+D32 -> 48
B33: MAESTRO MINERÍA - OOCC | C33: 56 | D33: 32 | E33: =C33+D33 -> 88
B34: AYUDANTE MINERÍA - OOCC | C34: 24 | D34: 0 | E34: =C34+D34 -> 24
B35: SOLDADOR MONTAJE (MINERÍA Y OOCC) | C35: 0 | D35: 16 | E35: =C35+D35 -> 16
B36: SUPERVISOR MONTAJE | C36: 0 | D36: 1 | E36: =C36+D36 -> 1
B37: CAPATAZ MONTAJE | C37: 4 | D37: 0 | E37: =C37+D37 -> 4
B38: MAESTRO MONTAJE | C38: 12 | D38: 0 | E38: =C38+D38 -> 12
B39: AYUDANTE MONTAJE | C39: 4 | D39: 0 | E39: =C39+D39 -> 4
... B45: SOLDADOR MONTAJE MISCELÁNEOS | C45: 0 | D45: 1 | E45: =C45+D45 -> 1
B46: CD+CI | C46: =SUM(C3:C45) -> 259 | D46: =SUM(D3:D45) -> 149 | E46: =SUM(E3:E45) -> 408
B48: ADMINISTRADOR DE CONTRATO | C48: 1 | D48: 0 | E48: =C48+D48 -> 1
B49: JEFE DE TERRENO | C49: 2 | D49: 0 | E49: =C49+D49 -> 2
B50: JEFE DE OPERACIONES | C50: 1 | D50: 0 | E50: =C50+D50 -> 1
B51: JEFE OFICINA TECNICA | C51: 1 | D51: 0 | E51: =C51+D51 -> 1
B52: INGENIERO PROGRAMACION Y CONTROL | C52: 1 | D52: 1 | E52: =C52+D52 -> 2
B53: INGENIERO OF. TECNICA A | C53: 1 | D53: 0 | E53: =C53+D53 -> 1
B54: INGENIERO OF. TECNICA B | C54: 1 | D54: 0 | E54: =C54+D54 -> 1
B55: JEFE SALA DE CONTROL | C55: 0 | D55: 1 | E55: =C55+D55 -> 1
B56: ENCARGADO DE CALIDAD | C56: 1 | D56: 0 | E56: =C56+D56 -> 1
B57: INSPECTOR DE CALIDAD | C57: 0 | D57: 2 | E57: =C57+D57 -> 2
B58: TOPOGRAFO | C58: 1 | D58: 0 | E58: =C58+D58 -> 1
...

Sheet Dotación por Depto
B2: CARGO | C2: ECO05 | D2: ODS N°1 | E2: TOTAL
B3: ADC
B4: ADMINISTRADOR DE CONTRATO | C4: 1 | D4: 0 | E4: =C4+D4 -> 1
B5: ÁREA OPERACIONES
B6: JEFE DE TERRENO | C6: 2 | D6: 0 | E6: =C6+D6 -> 2
B7: JEFE DE OPERACIONES | C7: 1 | D7: 0 | E7: =C7+D7 -> 1
B8: JEFE DE TURNO | C8: 4 | D8: 4 | E8: =C8+D8 -> 8
B9: CUADRILLAS MINERÍA Y OOCC
B10: CAPATAZ MINERIA - OOCC | C10: 32 | D10: 16 | E10: =C10+D10 -> 48
B11: MAESTRO MINERÍA - OOCC | C11: 56 | D11: 32 | E11: =C11+D11 -> 88
B12: AYUDANTE MINERÍA - OOCC | C12: 24 | D12: 0 | E12: =C12+D12 -> 24
B13: SOLDADOR MONTAJE (MINERÍA Y OOCC) | C13: 0 | D13: 16 | E13: =C13+D13 -> 16
B14: OPERADOR EQUIPO LEVANTE | C14: 32 | D14: 16 | E14: =C14+D14 -> 48
B15: CUADRILLA MONTAJE
B16: SUPERVISOR MONTAJE | C16: 0 | D16: 1 | E16: =C16+D16 -> 1
B17: CAPATAZ MONTAJE | C17: 4 | D17: 0 | E17: =C17+D17 -> 4
B18: MAESTRO MONTAJE | C18: 12 | D18: 0 | E18: =C18+D18 -> 12
B19: AYUDANTE MONTAJE | C19: 4 | D19: 0 | E19: =C19+D19 -> 4
B20: SOLDADOR MONTAJE | C20: 4 | D20: 0 | E20: =C20+D20 -> 4
B21: CUADRILLA MISCELÁNEOS
B22: CAPATAZ MISCELÁNEOS | C22: 0 | D22: 1 | E22: =C22+D22 -> 1
B23: MAESTRO AVANZADO MISCELÁNEOS | C23: 0 | D23: 1 | E23: =C23+D23 -> 1
B24: MAESTRO OOCC MISCELÁNEOS | C24: 0 | D24: 1 | E24: =C24+D24 -> 1
B25: AYUDANTE MISCELÁNEOS | C25: 0 | D25: 1 | E25: =C25+D25 -> 1
B26: SOLDADOR MONTAJE MISCELÁNEOS | C26: 0 | D26: 1 | E26: =C26+D26 -> 1
B27: OPERADORES
B28: OPERADOR JUMBO FORTIFICACION | C28: 8 | D28: 4 | E28: =C28+D28 -> 12
B29: OPERADOR JUMBO RADIAL | C29: 4 | D29: 0 | E29: =C29+D29 -> 4
B30: OPERADOR BOLTEC | C30: 0 | D30: 4 | E30: =C30+D30 -> 4
B31: OPERADOR BROKK | C31: 0 | D31: 4 | E31: =C31+D31 -> 4
B32: OPERADOR SCOOP | C32: 8 | D32: 0 | E32: =C32+D32 -> 8
B33: OPERADOR ROBOSHOT | C33: 4 | D33: 4 | E33: =C33+D33 -> 8
B34: OPERADOR RETROEXCAVADORA - ACUÑADOR | C34: 8 | D34: 0 | E34: =C34+D34 -> 8
B35: OPERADOR MIXER | C35: 0 | D35: 8 | E35: =C35+D35 -> 8
B36: CHOFER SERVICIOS (EXPLOSIVOS) | C36: 4 | D36: 0 | E36: =C36+D36 -> 4
B37: CHOFER SERVICIOS (CAMIONETAS) | C37: 7 | D37: 1 | E37: =C37+D37 -> 8
B38: ÁREA MAQUINARIA
B39: JEFE MAQUINARIA | C39: 1 | D39: 0 | E39: =C39+D39 -> 1
B40: SUPERVISOR MECÁNICO | C40: 0 | D40: 1 | E40: =C40+D40 -> 1
B41: SECRETARIO TECNICO MAQUINARIA | C41: 0 | D41: 1 | E41: =C41+D41 -> 1
...

Sheet Resumen Vacantes
A1: RESUMEN AUTOMÁTICO DE VACANTES
A2: Fuente: MANO DE OBRA | Filas 5 a 121 | Actualización automática
A4: DOTACIÓN TOTAL vs FALTANTE POR GRUPO
A5: Grupo | B5: Dotación | C5: Cubiertos | D5: Vacantes | E5: % Cubierto | F5: % Faltante
A6: GRUPO 1 | B6: =COUNTA('MANO DE OBRA'!F5:F116) -> 95 | C6: =B6-D6 -> 90 | D6: =COUNTIF('MANO DE OBRA'!F5:F116,"V*") -> 5 | E6: =C6/B6 -> 0.94736842 | F6: =D6/B6 -> 0.052631579
A7: GRUPO 2 | B7: =COUNTA('MANO DE OBRA'!H5:H121) -> 99 | C7: =B7-D7 -> 95 | D7: =COUNTIF('MANO DE OBRA'!H5:H121,"V*") -> 4 | E7: =C7/B7 -> 0.95959596 | F7: =D7/B7 -> 0.04040404
A8: GRUPO 3 | B8: =COUNTA('MANO DE OBRA'!K5:K116) -> 95 | C8: =B8-D8 -> 92 | D8: =COUNTIF('MANO DE OBRA'!K5:K116,"V*") -> 3 | E8: =C8/B8 -> 0.96842105 | F8: =D8/B8 -> 0.031578947
A9: GRUPO 4 | B9: =COUNTA('MANO DE OBRA'!N5:N121) -> 99 | C9: =B9-D9 -> 94 | D9: =COUNTIF('MANO DE OBRA'!N5:N121,"V*") -> 5 | E9: =C9/B9 -> 0.94949495 | F9: =D9/B9 -> 0.050505051
A10: TOTAL | B10: =SUM(B6:B9) -> 388 | C10: =SUM(C6:C9) -> 371 | D10: =SUM(D6:D9) -> 17 | E10: =C10/B10 -> 0.95618557 | F10: =D10/B10 -> 0.043814433
A12: RESUMEN POR TIPO DE VACANTE
A13: Tipo | B13: Descripción | C13: Cantidad | D13: % del Total
A14: V | B14: Vacante General | C14: =COUNTIF('MANO DE OBRA'!F5:F116,"V")+COUNTIF('MANO DE OBRA'!H5:H121,"V")+COUNTIF('MANO DE OBRA'!K5:K116,"V")+COUNTIF('MANO DE OBRA'!N5:N121,"V") -> 4 | D14: =IF(C21=0,0,C14/C21) -> 0.23529412
A15: V-M | B15: Vacante Minero/M1 | C15: =COUNTIF('MANO DE OBRA'!F5:F116,"V-M")+COUNTIF('MANO DE OBRA'!H5:H121,"V-M")+COUNTIF('MANO DE OBRA'!K5:K116,"V-M")+COUNTIF('MANO DE OBRA'!N5:N121,"V-M") -> 6 | D15: =IF(C21=0,0,C15/C21) -> 0.35294118
A16: V-BR | B16: Vacante Brokk | C16: =COUNTIF('MANO DE OBRA'!F5:F116,"V-BR")+COUNTIF('MANO DE OBRA'!H5:H121,"V-BR")+COUNTIF('MANO DE OBRA'!K5:K116,"V-BR")+COUNTIF('MANO DE OBRA'!N5:N121,"V-BR") -> 3 | D16: =IF(C21=0,0,C16/C21) -> 0.17647059
A17: V-MIX | B17: Vacante Mixer | C17: =COUNTIF('MANO DE OBRA'!F5:F116,"V-MIX")+COUNTIF('MANO DE OBRA'!H5:H121,"V-MIX")+COUNTIF('MANO DE OBRA'!K5:K116,"V-MIX")+COUNTIF('MANO DE OBRA'!N5:N121,"V-MIX") -> 2 | D17: =IF(C21=0,0,C17/C21) -> 0.11764706
A18: V-CS | B18: Vacante Chofer Servicios | C18: =COUNTIF('MANO DE OBRA'!F5:F116,"V-CS")+COUNTIF('MANO DE OBRA'!H5:H121,"V-CS")+COUNTIF('MANO DE OBRA'!K5:K116,"V-CS")+COUNTIF('MANO DE OBRA'!N5:N121,"V-CS") -> 1 | D18: =IF(C21=0,0,C18/C21) -> 0.058823529
A19: V-S | B19: Vacante Soldador | C19: =COUNTIF('MANO DE OBRA'!F5:F116,"V-S")+COUNTIF('MANO DE OBRA'!H5:H121,"V-S")+COUNTIF('MANO DE OBRA'!K5:K116,"V-S")+COUNTIF('MANO DE OBRA'!N5:N121,"V-S") -> 1 | D19: =IF(C21=0,0,C19/C21) -> 0.058823529
A20: Otros V-* | B20: Otros códigos V no listados | C20: =D10-SUM(C14:C19) -> 0 | D20: =IF(C21=0,0,C20/C21) -> 0
A21: TOTAL | C21: =SUM(C14:C20) -> 17 | D21: =SUM(D14:D20) -> 1
A23: DETALLE DE VACANTES POR GRUPO (AUTOMÁTICO)
A25: # | B25: Fila | C25: Departamento | D25: Cargo | E25: Estado | F25: Nombre
A26: {=IFERROR(_xlfn.SEQUENCE(D6),"")} -> 1 | B26: {=IFERROR(_xlfn._xlws.FILTER(ROW('MANO DE OBRA'!F5:F116),LEFT('MANO DE OBRA'!F5:F116,1)="V"),"")} -> 20 | C26: {=IFERROR(_xlfn._xlws.FILTER('MANO DE OBRA'!B5:B116,LEFT('MANO DE OBRA'!F5:F116,1)="V"),"")} -> MECANICO | D26: {=IFERROR(_xlfn._xlws.FILTER('MANO DE OBRA'!C5:C116,LEFT('MANO DE OBRA'!F5:F116,1)="V"),"")} -> MAESTRO MECÁNICO 3 | E26: {=IFERROR(_xlfn._xlws.FILTER('MANO DE OBRA'!F5:F116,LEFT('MANO DE OBRA'!F5:F116,1)="V"),"")} -> V | F26: {=IFERROR(IF(_xlfn._xlws.FILTER('MANO DE OBRA'!E5:E116,LEFT('MANO DE OBRA'!F5:F116,1)="V")=0,"(vacío)",_xlfn._xlws.FILTER('MANO DE OBRA'!E5:E116,LEFT('MANO DE OBRA'!F5:F116,1)="V")),"")} -> VACANTE
A27: 2 | B27: 39 | C27: OPERADOR | D27: OPERADOR MIXER | E27: V-MIX | F27: VACANTE
A28: 3 | B28: 41 | C28: OPERADOR | D28: OPERADOR BROKK | E28: V-BR | F28: VACANTE
A29: 4 | B29: 85 | C29: OPERACIÓN | D29: AYUDANTE | E29: V-M | F29: VACANTE
A30: 5 | B30: 96 | C30: OPERACIÓN | D30: MAESTRO M1 | E30: V-M | F30: (vacío)
A33: # | B33: Fila | C33: Departamento | D33: Cargo | E33: Estado | F33: Nombre
A34: {=IFERROR(_xlfn.SEQUENCE(D7),"")} -> 1 | B34: {=IFERROR(_xlfn._xlws.FILTER(ROW('MANO DE OBRA'!H5:H121),LEFT('MANO DE OBRA'!H5:H121,1)="V"),"")} -> 39 | C34: {=IFERROR(_xlfn._xlws.FILTER('MANO DE OBRA'!B5:B121,LEFT('MANO DE OBRA'!H5:H121,1)="V"),"")} -> OPERADOR | D34: {=IFERROR(_xlfn._xlws.FILTER('MANO DE OBRA'!C5:C121,LEFT('MANO DE OBRA'!H5:H121,1)="V"),"")} -> OPERADOR MIXER | E34: {=IFERROR(_xlfn._xlws.FILTER('MANO DE OBRA'!H5:H121,LEFT('MANO DE OBRA'!H5:H121,1)="V"),"")} -> V-MIX | F34: {=IFERROR(IF(_xlfn._xlws.FILTER('MANO DE OBRA'!G5:G121,LEFT('MANO DE OBRA'!H5:H121,1)="V")=0,"(vacío)",_xlfn._xlws.FILTER('MANO DE OBRA'!G5:G121,LEFT('MANO DE OBRA'!H5:H121,1)="V")),"")} -> VACANTE
A35: 2 | B35: 59 | C35: OPERACIÓN | D35: AYUDANTE | E35: V | F35: VACANTE
A36: 3 | B36: 74 | C36: OPERACIÓN | D36: MAESTRO M1 | E36: V-M | F36: VACANTE
A37: 4 | B37: 109 | C37: OPERACIÓN | D37: SOLDADOR | E37: V-S | F37: (vacío)
A41: # | B41: Fila | C41: Departamento | D41: Cargo | E41: Estado | F41: Nombre
A42: {=IFERROR(_xlfn.SEQUENCE(D8),"")} -> 1 | B42: {=IFERROR(_xlfn._xlws.FILTER(ROW('MANO DE OBRA'!K5:K116),LEFT('MANO DE OBRA'!K5:K116,1)="V"),"")} -> 41 | C42: {=IFERROR(_xlfn._xlws.FILTER('MANO DE OBRA'!B5:B116,LEFT('MANO DE OBRA'!K5:K116,1)="V"),"")} -> OPERADOR | D42: {=IFERROR(_xlfn._xlws.FILTER('MANO DE OBRA'!C5:C116,LEFT('MANO DE OBRA'!K5:K116,1)="V"),"")} -> OPERADOR BROKK | E42: {=IFERROR(_xlfn._xlws.FILTER('MANO DE OBRA'!K5:K116,LEFT('MANO DE OBRA'!K5:K116,1)="V"),"")} -> V-BR | F42: {=IFERROR(IF(_xlfn._xlws.FILTER('MANO DE OBRA'!J5:J116,LEFT('MANO DE OBRA'!K5:K116,1)="V")=0,"(vacío)",_xlfn._xlws.FILTER('MANO DE OBRA'!J5:J116,LEFT('MANO DE OBRA'!K5:K116,1)="V")),"")} -> VACANTE
A43: 2 | B43: 60 | C43: OPERADOR | D43: OPERADOR DE EQUIPO DE LEVANTE | E43: V | F43: VACANTE
A44: 3 | B44: 88 | C44: OPERACIÓN | D44: CAPATAZ MINERÍA - OOCC | E44: V | F44: VACANTE
A49: # | B49: Fila | C49: Departamento | D49: Cargo | E49: Estado | F49: Nombre
A50: {=IFERROR(_xlfn.SEQUENCE(D9),"")} -> 1 | B50: {=IFERROR(_xlfn._xlws.FILTER(ROW('MANO DE OBRA'!N5:N121),LEFT('MANO DE OBRA'!N5:N121,1)="V"),"")} -> 26 | C50: {=IFERROR(_xlfn._xlws.FILTER('MANO DE OBRA'!B5:B121,LEFT('MANO DE OBRA'!N5:N121,1)="V"),"")} -> OPERACIÓN | D50: {=IFERROR(_xlfn._xlws.FILTER('MANO DE OBRA'!C5:C121,LEFT('MANO DE OBRA'!N5:N121,1)="V"),"")} -> CHOFER DE SERVICIOS 4 | E50: {=IFERROR(_xlfn._xlws.FILTER('MANO DE OBRA'!N5:N121,LEFT('MANO DE OBRA'!N5:N121,1)="V"),"")} -> V-CS | F50: {=IFERROR(IF(_xlfn._xlws.FILTER('MANO DE OBRA'!M5:M121,LEFT('MANO DE OBRA'!N5:N121,1)="V")=0,"(vacío)",_xlfn._xlws.FILTER('MANO DE OBRA'!M5:M121,LEFT('MANO DE OBRA'!N5:N121,1)="V")),"")} -> VACANTE
A51: 2 | B51: 41 | C51: OPERADOR | D51: OPERADOR BROKK | E51: V-BR | F51: VACANTE
A52: 3 | B52: 58 | C52: OPERACIÓN | D52: MAESTRO M1 | E52: V-M | F52: VACANTE
A53: 4 | B53: 59 | C53: OPERACIÓN | D53: AYUDANTE | E53: V-M | F53: VACANTE
...
